2022-04-21 14:31:18,155 INFO  ==============================================================
2022-04-21 14:31:18,156 INFO  Id:    SoftwareManagement.Plugin.apama_plugin_mon_support
2022-04-21 14:31:18,157 INFO  Dir:   plugin_apama/
2022-04-21 14:31:18,158 INFO  Title: Validate mon file support of apama plugin
2022-04-21 14:31:18,159 INFO  ==============================================================
2022-04-21 14:31:18,188 WARN  Assertion that path exists=False for "/etc/tedge/apama/project" ... failed 
2022-04-21 14:31:18,700 INFO  Executed sudo<create_project_dir>, exit status 0
2022-04-21 14:41:18,722 WARN  Process sudo<unzip_apama_project> (pid 23801) timed out after 600 seconds, stopping process
2022-04-21 14:41:18,725 WARN  ProcessError occurred while running test - Error stopping process sudo<unzip_apama_project> (pid 23801) due to PermissionError: [Errno 1] Operation not permitted
Traceback (most recent call last):
  File "/home/pi/env-pysys/lib/python3.7/site-packages/pysys/process/user.py", line 465, in startProcess
    process.start()
  File "/home/pi/env-pysys/lib/python3.7/site-packages/pysys/process/__init__.py", line 282, in start
    self.wait(self.timeout)
  File "/home/pi/env-pysys/lib/python3.7/site-packages/pysys/process/__init__.py", line 263, in wait
    raise ProcessTimeout('Waiting for completion of %r timed out after %d seconds'%(self, int(timeout)))
pysys.exceptions.ProcessTimeout: Waiting for completion of sudo<unzip_apama_project> (pid 23801) timed out after 600 seconds

During handling of the above exception, another exception occurred:

Traceback (most recent call last):
  File "/home/pi/env-pysys/lib/python3.7/site-packages/pysys/process/plat-unix/helper.py", line 226, in stop
    os.kill(self.pid, sig)
PermissionError: [Errno 1] Operation not permitted

During handling of the above exception, another exception occurred:

Traceback (most recent call last):
  File "/home/pi/env-pysys/lib/python3.7/site-packages/pysys/baserunner.py", line 1292, in __call__
    self.testObj.setup()
  File "/home/pi/actions-runner/_work/thin-edge.io/thin-edge.io/tests/PySys/plugin_apama/apama_plugin_mon_support/run.py", line 19, in setup
    self.install_project(self.project.apama_input_dir + "/quickstart.zip")
  File "/home/pi/actions-runner/_work/thin-edge.io/thin-edge.io/tests/PySys/plugin_apama/environment_apama_plugin.py", line 72, in install_project
    stdouterr="unzip_apama_project",
  File "/home/pi/env-pysys/lib/python3.7/site-packages/pysys/process/user.py", line 493, in startProcess
    process.stop()
  File "/home/pi/env-pysys/lib/python3.7/site-packages/pysys/process/plat-unix/helper.py", line 252, in stop
    raise ProcessError("Error stopping process %r due to %s: %s"%(self, type(ex).__name__, ex))
pysys.exceptions.ProcessError: Error stopping process sudo<unzip_apama_project> (pid 23801) due to PermissionError: [Errno 1] Operation not permitted
2022-04-21 14:41:18,902 WARN  ProcessError: Error stopping process sudo<unzip_apama_project> (pid 23801) due to PermissionError: [Errno 1] Operation not permitted ... blocked 
2022-04-21 14:41:18,904 INFO  
2022-04-21 14:41:18,905 INFO  cleanup:
2022-04-21 14:41:18,908 INFO  Removing apama project
2022-04-21 14:41:19,420 WARN  Executed sudo<remove_apama_project>, exit status 1
2022-04-21 14:41:19,425 INFO  Contents of remove_apama_project.err: 
2022-04-21 14:41:19,426 INFO    rm: cannot remove '/etc/tedge/apama/project/logs/.nfs00000000000e0e1700000bb3': Device or resource busy
2022-04-21 14:41:19,427 INFO    -----
2022-04-21 14:41:19,427 INFO  
2022-04-21 14:41:19,458 ERROR Error while running cleanup function: 
Traceback (most recent call last):
  File "/home/pi/env-pysys/lib/python3.7/site-packages/pysys/process/user.py", line 1305, in cleanup
    fn()
  File "/home/pi/actions-runner/_work/thin-edge.io/thin-edge.io/tests/PySys/plugin_apama/environment_apama_plugin.py", line 144, in cleanup_project
    self.remove_project()
  File "/home/pi/actions-runner/_work/thin-edge.io/thin-edge.io/tests/PySys/plugin_apama/environment_apama_plugin.py", line 95, in remove_project
    stdouterr="remove_apama_project",
  File "/home/pi/env-pysys/lib/python3.7/site-packages/pysys/process/user.py", line 482, in startProcess
    abortOnError=abortOnError)
  File "/home/pi/env-pysys/lib/python3.7/site-packages/pysys/process/user.py", line 1401, in addOutcome
    self.abort(outcome, outcomeReason, callRecord)
  File "/home/pi/env-pysys/lib/python3.7/site-packages/pysys/process/user.py", line 1420, in abort
    raise AbortExecution(outcome, outcomeReason, callRecord)
pysys.exceptions.AbortExecution: sudo<remove_apama_project> returned non-zero exit code 1
2022-04-21 14:41:19,471 WARN  Cleanup failed with 1 errors: Cleanup function failed: sudo<remove_apama_project> returned non-zero exit code 1 (AbortExecution) ... blocked 
2022-04-21 14:41:19,475 INFO  
2022-04-21 14:41:19,476 INFO  Test duration: 601.33 secs
2022-04-21 14:41:19,477 INFO  Test final outcome:  BLOCKED
2022-04-21 14:41:19,477 INFO  Test outcome reason: ProcessError: Error stopping process sudo<unzip_apama_project> (pid 23801) due to PermissionError: [Errno 1] Operation not permitted (+3 other failures)
2022-04-21 14:41:19,478 INFO  
