<?xml version="1.0" encoding="utf-8"?>
<testsuite failures="1" name="SoftwareManagement.Plugin.apama_plugin_remove" skipped="0" tests="1" time="0.65" timestamp="2022-04-27T18:39:46">
	<testcase classname="ApamaPluginRemoveTest" name="SoftwareManagement.Plugin.apama_plugin_remove">
		<failure message="BLOCKED: sudo&lt;remove_apama_project&gt; returned non-zero exit code 1 (+2 other failures)" type="BLOCKED"/>
		<system-out>18:39:45 INFO  ==============================================================
18:39:45 INFO  Id:    SoftwareManagement.Plugin.apama_plugin_remove
18:39:45 INFO  Dir:   plugin_apama/
18:39:45 INFO  Title: Validate apama plugin remove
18:39:45 INFO  ==============================================================
18:39:45 WARN  Assertion that path exists=False for &quot;/etc/tedge/apama/project&quot; ... failed 
18:39:45 WARN  Aborted test due to FAILED outcome
18:39:45 INFO  
18:39:45 INFO  cleanup:
18:39:45 INFO  Removing apama project
18:39:46 WARN  Executed sudo&lt;remove_apama_project&gt;, exit status 1
18:39:46 INFO  Contents of remove_apama_project.err: 
  rm: cannot remove '/etc/tedge/apama/project/logs/.nfs00000000000e13ec00003dec': Device or resource busy
  -----

18:39:46 ERROR Error while running cleanup function: 
Traceback (most recent call last):
  File &quot;/home/pi/env-pysys/lib/python3.7/site-packages/pysys/process/user.py&quot;, line 1305, in cleanup
    fn()
  File &quot;/home/pi/actions-runner/_work/thin-edge.io/thin-edge.io/tests/PySys/plugin_apama/environment_apama_plugin.py&quot;, line 144, in cleanup_project
    self.remove_project()
  File &quot;/home/pi/actions-runner/_work/thin-edge.io/thin-edge.io/tests/PySys/plugin_apama/environment_apama_plugin.py&quot;, line 95, in remove_project
    stdouterr=&quot;remove_apama_project&quot;,
  File &quot;/home/pi/env-pysys/lib/python3.7/site-packages/pysys/process/user.py&quot;, line 482, in startProcess
    abortOnError=abortOnError)
  File &quot;/home/pi/env-pysys/lib/python3.7/site-packages/pysys/process/user.py&quot;, line 1401, in addOutcome
    self.abort(outcome, outcomeReason, callRecord)
  File &quot;/home/pi/env-pysys/lib/python3.7/site-packages/pysys/process/user.py&quot;, line 1420, in abort
    raise AbortExecution(outcome, outcomeReason, callRecord)
pysys.exceptions.AbortExecution: sudo&lt;remove_apama_project&gt; returned non-zero exit code 1
18:39:46 WARN  Cleanup failed with 1 errors: Cleanup function failed: sudo&lt;remove_apama_project&gt; returned non-zero exit code 1 (AbortExecution) ... blocked 
18:39:46 INFO  
18:39:46 INFO  Test duration: 0.65 secs
18:39:46 INFO  Test final outcome:  BLOCKED
18:39:46 INFO  Test outcome reason: sudo&lt;remove_apama_project&gt; returned non-zero exit code 1 (+2 other failures)
18:39:46 INFO  
</system-out>
	</testcase>
</testsuite>
