<?xml version="1.0" encoding="utf-8"?>
<testsuite failures="1" name="runtime_start_two_mappers" skipped="0" tests="1" time="0.61" timestamp="2022-04-27T10:31:10">
	<testcase classname="RuntimeMultiMappers" name="runtime_start_two_mappers">
		<failure message="BLOCKED: sudo&lt;tedge_mapper1&gt; returned non-zero exit code 1" type="BLOCKED"/>
		<system-out>10:31:09 INFO  ==============================================================
10:31:09 INFO  Id:    runtime_start_two_mappers
10:31:09 INFO  Dir:   tedge_mapper_c8y/
10:31:09 INFO  Title: Validate two mappers can't be started at the same time
10:31:09 INFO  ==============================================================
10:31:10 WARN  Executed sudo&lt;tedge_mapper1&gt;, exit status 1
10:31:10 INFO  Contents of tedge_mapper1.err: 
  Job for tedge-mapper-c8y.service failed because the control process exited with error code.
  See &quot;systemctl status tedge-mapper-c8y.service&quot; and &quot;journalctl -xe&quot; for details.
  -----

10:31:10 WARN  sudo&lt;tedge_mapper1&gt; returned non-zero exit code 1 ... blocked [run.py:26]
10:31:10 WARN  Aborted test due to BLOCKED outcome
10:31:10 INFO  
10:31:10 INFO  Test duration: 0.61 secs
10:31:10 INFO  Test final outcome:  BLOCKED
10:31:10 INFO  Test outcome reason: sudo&lt;tedge_mapper1&gt; returned non-zero exit code 1
10:31:10 INFO  
</system-out>
	</testcase>
</testsuite>
