2022-04-25 22:03:55,856 INFO  ==============================================================
2022-04-25 22:03:55,857 INFO  Id:    SoftwareManagement.Plugin.apama_plugin_install
2022-04-25 22:03:55,860 INFO  Dir:   plugin_apama/
2022-04-25 22:03:55,861 INFO  Title: Validate apama plugin install
2022-04-25 22:03:55,862 INFO  ==============================================================
2022-04-25 22:03:56,116 WARN  Assertion that path exists=False for "/etc/tedge/apama/project" ... failed 
2022-04-25 22:03:56,728 WARN  Executed sudo<plugin_install>, exit status 2
2022-04-25 22:03:56,736 INFO  Contents of plugin_install.err: 
2022-04-25 22:03:56,737 INFO    ERROR: Device or resource busy (os error 16)
2022-04-25 22:03:56,738 INFO    -----
2022-04-25 22:03:56,738 INFO  
2022-04-25 22:03:56,753 WARN  sudo<plugin_install> returned non-zero exit code 2 ... blocked [run.py:29]
2022-04-25 22:03:56,755 WARN  Aborted test due to BLOCKED outcome
2022-04-25 22:03:56,760 INFO  
2022-04-25 22:03:56,761 INFO  cleanup:
2022-04-25 22:03:56,762 INFO  Removing apama project
2022-04-25 22:03:57,322 WARN  Executed sudo<remove_apama_project>, exit status 1
2022-04-25 22:03:57,344 INFO  Contents of remove_apama_project.err: 
2022-04-25 22:03:57,345 INFO    rm: cannot remove '/etc/tedge/apama/project/logs/.nfs00000000000212fd00001804': Device or resource busy
2022-04-25 22:03:57,346 INFO    -----
2022-04-25 22:03:57,346 INFO  
2022-04-25 22:03:57,377 ERROR Error while running cleanup function: 
Traceback (most recent call last):
  File "/home/pi/env-pysys/lib/python3.7/site-packages/pysys/process/user.py", line 1305, in cleanup
    fn()
  File "/home/pi/actions-runner/_work/thin-edge.io/thin-edge.io/tests/PySys/plugin_apama/environment_apama_plugin.py", line 144, in cleanup_project
    self.remove_project()
  File "/home/pi/actions-runner/_work/thin-edge.io/thin-edge.io/tests/PySys/plugin_apama/environment_apama_plugin.py", line 95, in remove_project
    stdouterr="remove_apama_project",
  File "/home/pi/env-pysys/lib/python3.7/site-packages/pysys/process/user.py", line 482, in startProcess
    abortOnError=abortOnError)
  File "/home/pi/env-pysys/lib/python3.7/site-packages/pysys/process/user.py", line 1401, in addOutcome
    self.abort(outcome, outcomeReason, callRecord)
  File "/home/pi/env-pysys/lib/python3.7/site-packages/pysys/process/user.py", line 1420, in abort
    raise AbortExecution(outcome, outcomeReason, callRecord)
pysys.exceptions.AbortExecution: sudo<remove_apama_project> returned non-zero exit code 1
2022-04-25 22:03:57,390 WARN  Cleanup failed with 1 errors: Cleanup function failed: sudo<remove_apama_project> returned non-zero exit code 1 (AbortExecution) ... blocked 
2022-04-25 22:03:57,393 INFO  
2022-04-25 22:03:57,394 INFO  Test duration: 1.55 secs
2022-04-25 22:03:57,395 INFO  Test final outcome:  BLOCKED
2022-04-25 22:03:57,396 INFO  Test outcome reason: sudo<plugin_install> returned non-zero exit code 2 (+2 other failures)
2022-04-25 22:03:57,397 INFO  
