2022-04-27 10:29:06,302 INFO  ==============================================================
2022-04-27 10:29:06,303 INFO  Id:    mqtt_port_set
2022-04-27 10:29:06,304 INFO  Dir:   misc_features/
2022-04-27 10:29:06,305 INFO  Title: mqtt port set
2022-04-27 10:29:06,306 INFO  ==============================================================
2022-04-27 10:29:06,822 INFO  Executed sudo<mqtt_port_set>, exit status 0
2022-04-27 10:29:07,334 INFO  Executed sudo<tedge_get>, exit status 0
2022-04-27 10:29:07,340 INFO  Grep on file tedge_get.out ... passed
2022-04-27 10:29:07,345 INFO  Grep on file /etc/tedge/tedge.toml ... passed
2022-04-27 10:29:07,351 INFO  
2022-04-27 10:29:07,352 INFO  cleanup:
2022-04-27 10:29:07,919 INFO  Executed sudo<mqtt_port_unset>, exit status 0
2022-04-27 10:29:08,632 WARN  Executed sudo<tedge_connect_c8y>, exit status 1
2022-04-27 10:29:08,638 INFO  Contents of tedge_connect_c8y.err: 
2022-04-27 10:29:08,639 INFO    Error: failed to connect Cumulocity cloud.
2022-04-27 10:29:08,641 INFO    Caused by:
2022-04-27 10:29:08,643 INFO        A value for `c8y.url` is missing.
2022-04-27 10:29:08,644 INFO            A value can be set with `tedge config set c8y.url <value>`
2022-04-27 10:29:08,645 INFO    -----
2022-04-27 10:29:08,646 INFO  
2022-04-27 10:29:08,734 ERROR Error while running cleanup function: 
Traceback (most recent call last):
  File "/home/pi/env-pysys/lib/python3.7/site-packages/pysys/process/user.py", line 1305, in cleanup
    fn()
  File "/home/pi/actions-runner/_work/thin-edge.io/thin-edge.io/tests/PySys/misc_features/mqtt_port_set/run.py", line 50, in mqtt_cleanup
    self.tedge_connect_c8y()
  File "/home/pi/actions-runner/_work/thin-edge.io/thin-edge.io/tests/PySys/environments/environment_tedge.py", line 58, in tedge_connect_c8y
    expectedExitStatus=expectedExitStatus,
  File "/home/pi/env-pysys/lib/python3.7/site-packages/pysys/process/user.py", line 482, in startProcess
    abortOnError=abortOnError)
  File "/home/pi/env-pysys/lib/python3.7/site-packages/pysys/process/user.py", line 1401, in addOutcome
    self.abort(outcome, outcomeReason, callRecord)
  File "/home/pi/env-pysys/lib/python3.7/site-packages/pysys/process/user.py", line 1420, in abort
    raise AbortExecution(outcome, outcomeReason, callRecord)
pysys.exceptions.AbortExecution: sudo<tedge_connect_c8y> returned non-zero exit code 1
2022-04-27 10:29:08,754 WARN  Cleanup failed with 1 errors: Cleanup function failed: sudo<tedge_connect_c8y> returned non-zero exit code 1 (AbortExecution) ... blocked 
2022-04-27 10:29:08,759 INFO  
2022-04-27 10:29:08,760 INFO  Test duration: 2.46 secs
2022-04-27 10:29:08,762 INFO  Test final outcome:  BLOCKED
2022-04-27 10:29:08,764 INFO  Test outcome reason: sudo<tedge_connect_c8y> returned non-zero exit code 1 (+1 other failures)
2022-04-27 10:29:08,766 INFO  
