<?xml version="1.0" encoding="utf-8"?>
<testsuite failures="1" name="SoftwareManagement.Plugin.apama_plugin_update" skipped="0" tests="1" time="0.72" timestamp="2022-04-25T22:26:34">
	<testcase classname="ApamaPluginUpdateTest" name="SoftwareManagement.Plugin.apama_plugin_update">
		<failure message="BLOCKED: sudo&lt;remove_apama_project&gt; returned non-zero exit code 1 (+2 other failures)" type="BLOCKED"/>
		<system-out>22:26:34 INFO  ==============================================================
22:26:34 INFO  Id:    SoftwareManagement.Plugin.apama_plugin_update
22:26:34 INFO  Dir:   plugin_apama/
22:26:34 INFO  Title: Validate apama plugin updating one project with another
22:26:34 INFO  ==============================================================
22:26:34 WARN  Assertion that path exists=False for &quot;/etc/tedge/apama/project&quot; ... failed 
22:26:34 WARN  Aborted test due to FAILED outcome
22:26:34 INFO  
22:26:34 INFO  cleanup:
22:26:34 INFO  Removing apama project
22:26:34 WARN  Executed sudo&lt;remove_apama_project&gt;, exit status 1
22:26:34 INFO  Contents of remove_apama_project.err: 
  rm: cannot remove '/etc/tedge/apama/project/logs/.nfs0000000000160ecc00001e56': Device or resource busy
  -----

22:26:34 ERROR Error while running cleanup function: 
Traceback (most recent call last):
  File &quot;/home/pi/env-pysys/lib/python3.7/site-packages/pysys/process/user.py&quot;, line 1305, in cleanup
    fn()
  File &quot;/home/pi/actions-runner/_work/thin-edge.io/thin-edge.io/tests/PySys/plugin_apama/environment_apama_plugin.py&quot;, line 144, in cleanup_project
    self.remove_project()
  File &quot;/home/pi/actions-runner/_work/thin-edge.io/thin-edge.io/tests/PySys/plugin_apama/environment_apama_plugin.py&quot;, line 95, in remove_project
    stdouterr=&quot;remove_apama_project&quot;,
  File &quot;/home/pi/env-pysys/lib/python3.7/site-packages/pysys/process/user.py&quot;, line 482, in startProcess
    abortOnError=abortOnError)
  File &quot;/home/pi/env-pysys/lib/python3.7/site-packages/pysys/process/user.py&quot;, line 1401, in addOutcome
    self.abort(outcome, outcomeReason, callRecord)
  File &quot;/home/pi/env-pysys/lib/python3.7/site-packages/pysys/process/user.py&quot;, line 1420, in abort
    raise AbortExecution(outcome, outcomeReason, callRecord)
pysys.exceptions.AbortExecution: sudo&lt;remove_apama_project&gt; returned non-zero exit code 1
22:26:34 WARN  Cleanup failed with 1 errors: Cleanup function failed: sudo&lt;remove_apama_project&gt; returned non-zero exit code 1 (AbortExecution) ... blocked 
22:26:34 INFO  
22:26:34 INFO  Test duration: 0.72 secs
22:26:34 INFO  Test final outcome:  BLOCKED
22:26:34 INFO  Test outcome reason: sudo&lt;remove_apama_project&gt; returned non-zero exit code 1 (+2 other failures)
22:26:34 INFO  
</system-out>
	</testcase>
</testsuite>
